package lab2;
class MyException extends Exception {
    //public MyException () {}
    public String toString () { return "MyException happened";}
}

/**
 * Следующий пример иллюстрирует выброс и перехват собственного исключения.
 */
public class Example5 {
    static void Func() throws MyException {
        int m = 0, n = 10;
        if((m/n) == 0) throw new MyException ();
        System.out.print ("Next");
    }
    public static void main(String[] args) {
        try
        {Func ();}
        catch (MyException e) {System.out.println (e);}
    }

}
